Workbook

Sheet 99_Lookups
A1: Level | B1: Num
A2: L | B2: 1
A3: M | B3: 2
A4: H | B4: 3

Sheet 00_Dashboard
A1: Vanguard Healthcare – Risicoanalyse (AD Cybersecurity) – Dashboard
A3: Voortgang & KPI's
A4: Metric | B4: Waarde
A5: Aantal assets (02_Assetregister) | B5: =COUNTA('02_Assetregister'!C2:C200) -> 199
A6: Aantal risico's (06_Risicoregister) | B6: =COUNTIF('06_Risicoregister'!$A$2:$A$200,"R*") -> 12
A7: Aantal Hoog risico | B7: =COUNTIF('06_Risicoregister'!$L$2:$L$200,"Hoog") -> 2
A8: Aantal scenario's (08_Scenarioanalyse) | B8: =COUNTIF('08_Scenarioanalyse'!$B$2:$B$200,"R*") -> 0
A9: Top-5 ingevuld (09_Top5_Risicos) | B9: =COUNTIF('09_Top5_Risicos'!$B$2:$B$6,"R*") -> 5
A10: Maatregelen ingevuld (10_Maatregelenplan) | B10: =COUNTIF('10_Maatregelenplan'!$C$2:$C$500,"<>") -> 0

Sheet 01_Scope_Context
A1: Veld | B1: In te vullen door student
A3: Organisatienaam | B3: Vanguard Healthcare
A4: Doel risicoanalyse | B4: Het doel van de risicoanalyse is het in kaart brengen van de belangrijkste cyber kwetsbaarheden voor Vanguard Healthcare, de aantoonbaarheid van de kwetsbaarheden zorgt ervoor dat er actie ondernomen kan worden tot het verbeteren van patiëntveiligheid, continuïtteit van Zorg en naleving van AVG/NIS2.
A5: Scope (in scope) | B5: Menselijke laag: gedrag, bewustzijn, kennis en vaardigheden van medewerkers, naleving van procedures, rollen, verantwoordelijkheden en autorisaties. Bedrijfsprocessenlaag: inrichting en uitvoering van zorg- en ondersteunende processen, taakverdeling, functiescheiding en onderlinge afhankelijkheden. Informatie-, data- en applicatielaag: gebruik en beheer van EZPD, Vanguard Connect, DLO, HR & Planning en Financiën & Declaraties, inclusief datastromen, autorisaties en informatiebeveiliging. Infrastructuurlaag: netwerken, servers, cloudvoorzieningen, werkplekken, identity & access management, back-up- en herstelvoorzieningen en technische beveiligingsmaatregelen.
A6: Out-of-scope | B6: Deze risicoanalyse richt zich op het formuleren van adviezen. De implementatie van verbetermaatregelen maakt geen onderdeel uit van deze opdracht. Zo worden er geen pentests uitgevoerd, het is gebaseerd op casus informatie. Daarnaast vallen de netwerken en devices van patiënten zelf buiten de scope. Onder andere vallen medische apparatuur en medsiche procedures die niet gebonden zijn aan een netwerk buiten de scope. Bovendien richt deze risicoanalyse zich niet op grootschalige IT-incidenten, maar op IT-risico's op structureel niveau binnen de dagelijkse bedrijfsvoering.
A7: Aanpak (methodiek) | B7: 4-lagenmodel, BIV, ISO 27005, NIST CSF
A8: Aannames (min. 5) | B8: MFA is niet verplicht, IT is voornamelijk gericht op beheer en niet op security, de organisatie is sterk afhankelijk van het EZPD, er wordt gewerkt met verouderde software en inloggegevens worden niet tijdig uit het systeem verwijderd.
A9: Beperkingen analyse | B9: De analyse is gebaseerd op de aangeleverde casusdocument en is daarmee beperkt tot de daarin opgenomen informatie. Er zijn geen interviews met de betrokken partijen, zoals processeigenaren/IT/MT. Daarnaast zijn er geen technische scans uitgevoerd. BIV-waarden zijn inschattingen, dat wil zeggen dat het exacte impact kan afwijken. Ten slotte is er geen volledige asset-inventaris, CMDB of detaildocumentaties over configuraties, logging en patchstanden.
A10: Datum | B10: 02/02/2026 - 03/12/2026
A11: Teamleden | B11: Mauzma & Viresh

Sheet 02_Assetregister
A1: Nr | B1: Organisatielaag | C1: Assetnaam | D1: Beschrijving | E1: Asset-owner (rol) | F1: B | G1: I | H1: V | I1: Motivatie BIV
A2: 1 | B2: Menselijkelaag | C2: Stagiairs & zorgstudenten | D2: Vanguard Healthcare werkt samen met opleidingsinstituten, waardoor stagiairs en zorgstudenten toegang krijgen tot interne leer- en informatiesystemen. | E2: Stagebegeleider | F2: M | G2: M | H2: M | I2: Beschikbaarheid is middelmatig: Omdat stagaires toegang tot leer en informatie systemen nodig hebben voor hun opeliding en begeleiding, maar uitval heeft geen directe impact op patiënten zorg. Integriteit is middelmatig: Omdat onjuiste of gewijzigde informatie in leer en reflectiedocumenten kan leiden to verkeerde interpretatie of beoordeling. Vertrouwlijkheid is middelmatig: Omdat documenten zijn bedoeld om geanonimiseerd te zijn, maar bevatten in praktijk soms indirect herleidbare patiënt informatie.
A3: 2 | B3: Menselijkelaag | C3: Zorgmedewerkers | D3: De organisatie telt ongeveer 1.100 medewerkers, waaronder artsen, verpleegkundigen en zorgcoördinatoren die dagelijks afhankelijk zijn van digitale systemen voor zorgverlening. | E3: Management | F3: H | G3: H | H3: H | I3: Beschikbaarheid is hoog: Omdat zorgmedewerkers dagelijks afhankelijk zijn van digitale systemen voor directe zorgverlening en patiëntveiligheid. Integriteit is hoog: Omdat onjuiste informatie kan leiden tot verkeerde medische besluiten. Vertrouwelijkheid is hoog: Omdat zorgmedewerkers met bijzondere persoonsgegevens werken, zoals medische gegevens.
A4: 3 | B4: Menselijkelaag | C4: Patiëntendossier | D4: het EZPD wordt gebruikt voor: Vastleggen en raadplegen van patiëntgegevens, Medicatiebeheer, Diagnostiek en behandelplannen, Communicatie met externe zorgpartners | E4: Management | F4: H | G4: H | H4: H | I4: Beschikbaarheid is hoog: Omdat constante beschikbaarheid essentieel is voor zorgverlening, medicatiebeheer en patiëntveiligheid. Integriteit is hoog: Omdat gemanipuleerde gegevens kunnen leiden tot verkeerde diagnoses en behandelingen. Vertrouwelijkheid is hoog: Omdat zorgmedewerkers met bijzondere persoonsgegevens werken, zoals medische gegevens en behandelplannen.
A5: 4 | B5: Menselijkelaag | C5: IT medewerkers | D5: De IT-afdeling is relatief klein en richt zich vooral op operationeel beheer van systemen en infrastructuur. | E5: Management | F5: M | G5: H | H5: H | I5: Beschikbaarheid is middel: Omdat IT medewerkers nodig zijn voor het beheer en herstel van systemen, maar tijdelijkse afwezigheid leidt niet direct tot zorguitval. Integriteit is hoog: Omdat onjuist handelen of fouten in beheer kunnen grote impact hebben op systeem en gegevens. Vertrouwelijkheid is hoog: Omdat IT medewerkers verhoogde toegangsrechten tot systeem en gevoelige gegevens.
A6: 5 | B6: Menselijkelaag | C6: Externe zorgprofessionals (buitenlandse of van huis uit medewerkers die medisch advies geven) | D6: Externe zorgprofessionals maken gebruik van een VPN-verbinding om toegang te krijgen tot interne systemen. | E6: Management | F6: M | G6: H | H6: H | I6: Beschikbaarheid is middelmatig: Omdat toegang tot systemen nodig is voor samenwerking en zorgcontinuïteit, maar uitval geeft meestal geen directe impact op de zorg. Integriteit is hoog: Omdat onjuiste of gewijzigde informatie kan leiden tot fouten in zorgverlening of overdracht. Vertrouwelijkheid is hoog: Omdat externe zorgprofessionals via VPN toegang hebben tot medische en persoonsgegevens.
A7: 6 | B7: Menselijkelaag | C7: Gebruikersaccounts | D7: Accounts worden niet altijd tijdig aangepast bij functiewijzigingen of het beëindigen van tijdelijke contracten. | E7: IT | F7: M | G7: H | H7: H | I7: Betrouwbaarheid is middelmatig: Omdat gebruikersaccounts beschikbaar moeten zijn zodat medewerkers hun werk kunnen uitvoeren. Als accounts niet goed zijn ingericht of te laat worden aangepast, kan dit leiden tot tijdelijke verstoringen in het werkproces, maar de zorg stopt niet direct volledig. Integriteit is hoog: Wanneer accounts niet tijdig worden aangepast bij functiewijzigingen of uitdiensttreding, bestaat het risico dat onbevoegden gegevens kunnen wijzigen. Dit kan leiden tot onjuiste of gemanipuleerde informatie, wat vooral in een zorgomgeving grote gevolgen kan hebben. Vertrouwelijkheid is hoog: Omdat verouderde of onterecht actieve accounts kunnen toegang geven tot gevoelige (patiënt)gegevens. Dit vergroot het risico op datalekken en schending van de AVG, waardoor de vertrouwelijkheid van informatie ernstig in gevaar komt.
A8: 7
A9: 8 | B9: Bedrijfsprocessen laag | C9: Zorgverlening | D9: Het kernproces van Vanguard Healthcare is het leveren van veilige, tijdige en kwalitatieve zorg, waarbij zorgverleners sterk afhankelijk zijn van digitale systemen. | E9: Management | F9: H | G9: H | H9: H | I9: Beschikbaarheid is hoog: Het zorgverleningsproces moet continu beschikbaar zijn. Uitval van digitale systemen kan direct leiden tot vertraging of stilstand van zorg, wat gevolgen heeft voor patiëntveiligheid en continuïteit van de organisatie. Integriteit is hoog: Zorgverlening is afhankelijk van correcte en actuele gegevens. Onjuiste of aangepaste informatie kan leiden tot verkeerde diagnoses, behandelingen of medicatie, met ernstige risico’s voor patiënten. Vertrouwlijkheid is hoog: Tijdens het zorgproces worden gevoelige patiëntgegevens verwerkt. Onbevoegde toegang tot deze gegevens kan leiden tot datalekken en overtreding van wetgeving zoals de AVG.
A10: 9 | B10: Bedrijfsprocessen laag | C10: Incidenten, waarschuwingssignalen en auditobservaties | D10: De IT-afdeling focust zich op onderhoud, niet op beveiliging. Problemen worden vooral opgelost als ze optreden, maar er wordt weinig gedaan om aanvallen vooraf te voorkomen. | E10: Management | F10: M | G10: H | H10: M | I10: Beschikbaarheid is middelmatig: Het proces rondom incidenten en waarschuwingen ondersteunt de continuïteit van IT-diensten, maar is niet direct zorgverlenend. Als dit proces tijdelijk minder goed functioneert, leidt dit niet meteen tot stilstand van zorg, maar verhoogt het wel de kans op verstoringen. Integriteit is hoog: Incidentmeldingen, loggegevens en auditobservaties moeten betrouwbaar en correct zijn. Als deze informatie onjuist of onvolledig is, kunnen risico’s verkeerd worden ingeschat en blijven kwetsbaarheden onopgemerkt. Vertrouwlijkheid is middelmatig: Incidentinformatie kan gevoelige technische en organisatorische details bevatten. Onbevoegde inzage kan misbruik in de hand werken, maar de gegevens zijn meestal minder gevoelig dan patiëntgegevens.
A11: 10 | B11: Bedrijfsprocessen laag | C11: Administratie | D11: Ondersteunende processen zoals administratie zijn sterk geautomatiseerd en gekoppeld aan het EZPD. | E11: IT | F11: M | G11: H | H11: H | I11: Beschikbaarheid is middelmatig: Administratieve processen zijn belangrijk voor de organisatie, maar ondersteunen vooral de zorgverlening. Tijdelijke uitval heeft niet direct invloed op patiëntveiligheid, maar kan wel leiden tot vertragingen en inefficiënties. Integriteit is hoog: Administratieve processen zijn gekoppeld aan het EZPD en verwerken gegevens zoals declaraties, dossiers en personeelsinformatie. Onjuiste of gewijzigde gegevens kunnen leiden tot fouten in facturatie, rapportages en besluitvorming. Vertrouwlijkheid is hoog: Binnen administratieve processen worden gevoelige persoonsgegevens en zorggerelateerde informatie verwerkt. Onbevoegde toegang kan leiden tot datalekken en overtreding van privacywetgeving zoals de AVG.
A12: 11 | B12: Bedrijfsprocessen laag | C12: HR & Planning | D12: Voor personeelsbeheer maakt Vanguard Healthcare gebruik van een Cloud gebaseerde HR- en planningsapplicatie. | E12: HR | F12: M | G12: H | H12: H | I12: Beschikbaarheid is middelmatig: HR- en planningsprocessen zijn belangrijk voor een goede bezetting, maar tijdelijke uitval leidt niet direct tot het stoppen van zorg. Wel kan het roosters verstoren en extra werkdruk veroorzaken. Integriteit is hoog: Het HR- en planningssysteem bevat gegevens over roosters, contracten en inzet van personeel. Onjuiste of aangepaste gegevens kunnen leiden tot verkeerde planning, onderbezetting en verstoring van zorgprocessen. Vertrouwlijkheid is hoog: In de cloudgebaseerde HR- en planningsapplicatie worden gevoelige persoonsgegevens van medewerkers verwerkt. Onbevoegde toegang kan leiden tot datalekken en schending van privacywetgeving.
A13: 12 | B13: Bedrijfsprocessen laag | C13: Financiën & Declaraties | D13: De financiële afhandeling van zorgverlening verloopt grotendeels digitaal via declaratie- en facturatiesystemen gekoppeld aan zorgverzekeraars Dit systeem ontvangt gegevens vanuit het EZPD over geleverde zorg, behandelingen en verrichtingen, en vertaalt deze naar declaraties richting externe partijen. | E13: Financiën afdeling | F13: M | G13: H | H13: H | I13: Beschikbaarheid is middelmatig: Financiële en declaratieprocessen zijn belangrijk voor de continuïteit van de organisatie, maar tijdelijke uitval heeft geen directe invloed op patiëntveiligheid. Wel kan het leiden tot vertraging in betalingen en inkomsten. Integriteit is hoog: Het declaratie- en facturatiesysteem ontvangt gegevens uit het EZPD over behandelingen en verrichtingen. Onjuiste of gemanipuleerde gegevens kunnen leiden tot foutieve declaraties, financiële schade en problemen met zorgverzekeraars. Vertrouwlijkheid is hoog: In dit proces worden financiële gegevens en zorggerelateerde persoonsgegevens verwerkt. Onbevoegde toegang kan leiden tot datalekken en overtreding van privacywetgeving.
A14: 13 | B14: Bedrijfsprocessen laag | C14: Samenwerking met externe partijen | D14: Vanguard Healthcare werkt samen met laboratoria, ICT-leveranciers en zorgverzekeraars waarbij gegevens digitaal worden uitgewisseld via API en beveiligde e-mail. | E14: Management | F14: M | G14: H | H14: H | I14: Beschikbaarheid is middelmatig: De samenwerking met externe partijen is belangrijk voor ondersteuning van zorgprocessen, zoals laboratoriumuitslagen en declaraties. Tijdelijke uitval van gegevensuitwisseling leidt meestal tot vertraging, maar niet direct tot volledige stilstand van zorgverlening. Integriteit is hoog: Gegevens worden digitaal uitgewisseld via API’s en beveiligde e-mail. Het is cruciaal dat deze gegevens correct en ongewijzigd worden ontvangen, omdat fouten kunnen leiden tot verkeerde medische of administratieve beslissingen. Vertrouwlijkheid is hoog: Bij de gegevensuitwisseling met externe partijen worden gevoelige (patiënt)gegevens gedeeld. Onbevoegde inzage of onderschepping kan leiden tot datalekken en schending van privacywetgeving zoals de AVG.
A15: 14
A16: 15 | B16: Informatie, data- en applicatielaag | C16: EZPD | D16: EZPD is het primaire informatiesysteem waarin patiëntgegevens, medicatie, diagnosen en behandelplannen worden vastgelegd en geraadpleegd. | E16: IT | F16: H | G16: H | H16: H | I16: Beschikbaarheid is hoog: Continue beschikbaarheid is noodzakelijk voor zorgverlening, medicatiebeheer en diagnostiek, uitval heeft directe impact op de patientveiligheid. Integriteit is Hoog: onjuiste of gemanipuleerde gegevens kunnen leiden tot verkeerde diagnoses of behandelingen. Vertrouwlijkheid is hoog: Het EZPD bevat bijzondere persoonsgegevens, zoals medische dossiers en behandelplannen
A17: 16 | B17: Informatie, data- en applicatielaag | C17: Vanguard Connect | D17: Vanguard Connect fungeert als het primaire patiëntenportaal voor e-consults, medische uitslagen, communicatie en afspraken beheren. | E17: IT | F17: H | G17: H | H17: H | I17: Beschikbaarheid is hoog: Beschikbaarheid is essentieel voor e-consults en zorg op afstand; uitval verstoort de continuïteit van zorg Integriteit is hoog: Onjuiste of gewijzigde informatie kan leiden tot verkeerde medische communicatie of besluitvorming Vertrouwlijkheid is hoog: Het platform verwerkt persoonsgegevens en bijzondere medische gegevens
A18: 17 | B18: Informatie, data- en applicatielaag | C18: DLO | D18: DLO wordt gebruikt voor opleiding, bijscholing, stageopdrachten en kennisdeling binnen de organisatie. | E18: IT | F18: H | G18: H | H18: H | I18: Beschikbaarheid is hoog: Beschikbaarheid is essentieel voor e-consults en digitale zorgverlening Integriteit is hoog: Onjuiste of gewijzigde informatie kan leiden tot verkeerde medische communicatie Vertrouwlijkheid is hoog: Verwerkt persoonsgegevens en bijzondere medische gegevens
A19: 18 | B19: Informatie, data- en applicatielaag | C19: HR & Planning applicatie | D19: Cloud gebaseerde applicatie voor roosterplanning, registratie van gewerkte uren, verlofaanvragen, beschikbaarheid en koppelingen met salarisverwerking. | E19: HR | F19: M | G19: H | H19: H | I19: Beschikbaarheid is hoog: Beschikbaarheid is belangrijk voor personeelsplanning, maar uitval heeft geen directe impact op de acute zorg Integriteit is hoog: onjuiste of gewijzigde gegevens kunnen leiden tot verkeerde roosters, loonfouten en operationele verstoringen Vertrouwlijkheid is hoog: Bevat persoonsgegevens van medewerkers, zoals contract- en werktijdgegevens
A20: 19 | B20: Informatie, data- en applicatielaag | C20: Financiën & Declaraties systeem | D20: Digitaal systeem voor declaraties en facturatie dat gegevens ontvangt vanuit het EZPD en declaraties richting zorgverzekeraars verzorgt via API-, EDI- en SFTP-koppelingen. | E20: Financiën afdeling | F20: M | G20: H | H20: H | I20: Beschikbaarheid is middel: Beschikbaarheid is belangrijk voor facturatie en declaraties, maar uitval heeft geen directe impact op de acute zorg Integriteit is hoog: Onjuiste of gewijzigde gegevens kunnen leiden tot foutieve declaraties en financiële schade. Vertrouwlijkheid is hoog: Verwerkt financiële gegevens en zorggerelateerde persoonsgegevens
A21: 20 | B21: Informatie, data- en applicatielaag | C21: Identity Management (Vanguard Healthcare) | D21: Identity management omgeving waarmee gebruikers authenticeren en autorisaties worden toegekend op basis van functie en rol, inclusief federatie voor zorgverleners. | E21: IT operations manager | F21: H | G21: H | H21: H | I21: Beschikbaarheid is hoog: Zonder IAM kunnen gebruikers zich niet authenticeren en krijgen zij geen toegang tot kritieke zorgsystemen Integriteit is hoog: onjuiste autorisaties kunnen leiden tot onbevoegde toegang of verstoring van systemen Vertrouwlijkheid is IAM beheert toegangsrechten tot systemen met bijzondere persoonsgegevens
A22: 21
A23: 22 | B23: Infrastructuur laag | C23: Netwerk infrastructuur | D23: Vanguard Healthcare maakt gebruik van een breed opgezet netwerk dat meerdere locaties met elkaar verbindt via een glasvezel KPN WAN. | E23: IT | F23: H | G23: H | H23: M | I23: Beschikbaarheid is hoog: Het netwerk is noodzakelijk voor verbinding tussen locaties en toegang tot zorg- en informatiesystemen Integriteit is hoog: Ongewenste wijzigingen of verstoringen in het netwerk kunnen leiden tot uitval of datamanipulatie Vertrouwlijkheid is middel: Het netwerk transporteert gevoelige gegevens, maar de vertrouwelijkheid wordt deels geborgd via versleuteling en applicatiebeveiliging
A24: 23 | B24: Infrastructuur laag | C24: VPN voor Externe zorgprofessionals | D24: Externe zorgprofessionals maken gebruik van een VPN-verbinding om toegang te krijgen tot interne systemen. | E24: IT | F24: H | G24: H | H24: H | I24: Beschikbaarheid is hoog: Zonder VPN kunnen externe zorgprofessionals geen toegang krijgen tot interne systemen en stagneert de samenwerking Integriteit is hoog: misconfiguratie of misbruik van de VPN kan leiden tot onbevoegde toegang of verstoring van systemen Vertrouwlijkheid is hoog: via de VPN wordt toegang verkregen tot systemen met (bijzondere) persoonsgegevens
A25: 24 | B25: Infrastructuur laag | C25: Cloudomgeving | D25: EZPD systeem wordt gehost in een hybride cloudomgeving, waarbij een externe leverancier verantwoordelijk is voor hosting, onderhoud en updates. | E25: IT | F25: H | G25: H | H25: H | I25: Beschikbaarheid is hoog: beschikbaarheid van de cloudomgeving is essentieel voor het functioneren van het EZPD en daarmee voor de continuïteit van zorg Integriteit is hoog: verstoringen of ongewenste wijzigingen in de cloudomgeving kunnen leiden tot dataverlies of systeemfouten Vertrouwlijkheid is hoog: De cloudomgeving verwerkt en bewaart bijzondere medische persoonsgegevens (AVG) via het EZPD
A26: 25 | B26: Infrastructuur laag | C26: Medische IoT-apparatuur | D26: Medische IoT-apparatuur zit op hetzelfde netwerksegment als werkplekken op sommige afdelingen. | E26: IT | F26: H | G26: H | H26: M | I26: Beschikbaarheid is hoog: Medische IoT-apparatuur wordt gebruikt tijdens de zorgverlening. Uitval of verstoring van deze apparatuur kan direct invloed hebben op de continuïteit van zorg en mogelijk op patiëntveiligheid. Integriteit is hoog: De apparatuur verwerkt en verstuurt meetgegevens die gebruikt worden door zorgverleners. Als deze gegevens worden aangepast of onjuist zijn, kan dit leiden tot verkeerde interpretaties en beslissingen. Vertrouwlijkheid is middelmatig: Medische IoT-apparatuur verwerkt soms patiëntgegevens, maar meestal in beperkte vorm. Doordat de apparatuur zich op hetzelfde netwerksegment bevindt als werkplekken, bestaat wel een verhoogd risico op ongeautoriseerde toegang, maar de gevoeligheid is vaak lager dan bij het EZPD.
A27: 26 | B27: Infrastructuur laag | C27: Verouderde software | D27: Een deel van de Medische apparatuur en zorgtechnologie draait op verouderde software en ontvangt niet structureel beveiligingsupdates. De apparatuur is functioneel noodzakelijk voor zorgverlening, maar vormt tegelijkertijd een potentieel aanvalsvlak binnen de IT-infrastructuur. | E27: IT | F27: H | G27: H | H27: M | I27: Beschikbaarheid is hoog: De medische apparatuur is functioneel noodzakelijk voor de zorgverlening. Uitval van deze systemen kan direct leiden tot vertraging of het niet kunnen uitvoeren van behandelingen, wat impact heeft op patiëntveiligheid. Integriteit is hoog: Verouderde software die geen beveiligingsupdates ontvangt, vergroot de kans op misbruik of manipulatie. Aangepaste of onjuiste werking van apparatuur kan leiden tot foutieve meetwaarden of zorgbeslissingen. Vertrouwlijkheid is middelmatig: De apparatuur verwerkt soms (beperkte) patiëntgegevens. Door het ontbreken van updates bestaat een verhoogd risico op ongeautoriseerde toegang, maar de hoeveelheid en gevoeligheid van de gegevens is doorgaans lager dan bij kernsystemen zoals het EZPD.
A28: 27 | B28: Infrastructuur laag | C28: Systeem Back-ups | D28: Back-ups van sommige systemen worden door leverancier beheerd; interne zichtbaarheid beperkt. | E28: IT | F28: H | G28: H | H28: H | I28: Beschikbaarheid is hoog: Back-ups zijn essentieel voor herstel na storingen of incidenten en daarmee voor de continuïteit van Integriteit is hoog: onjuiste, incomplete of corrupte back-ups kunnen leiden tot dataverlies of onbetrouwbaar herstel Vertrouwlijkheid is hoog: back-ups bevatten kopieën van systemen met (bijzondere) persoonsgegevens, waaronder medische gegevens
A29: 28
A30: 29 | B30: Bedrijfsprocessen laag | C30: reflectieverslagen/ cassusen gebaseerd op echte zorgsituaties | D30: In de DLO worden regelmatig casussen gebruikt die zijn gebaseerd op echte zorgsituaties. Hoewel deze casussen bedoeld zijn om geanonimiseerd te zijn, blijkt in de praktijk dat in reflectieverslagen soms indirect herleidbare patiëntinformatie wordt opgenomen | E30: Management | F30: L | G30: H | H30: H | I30: Beschikbaarheid is Laag: reflectieverslagen zijn belangrijk voor onderwijs en toetsing, maar tijdelijke onbeschikbaarheid leidt niet direct tot verstoring van primaire zorgprocessen. Integriteit is hoog: onjuiste of aangepaste verslagen kunnen leiden tot verkeerde beoordeling, misinterpretatie van zorgsituaties en aantasting van onderwijskwaliteit. Vertrouwelijkheid is hoog: verslagen kunnen (indirect) herleidbare patiëntinformatie bevatten, waaronder mogelijk bijzondere persoonsgegevens zoals medische gegevens, wat bij onbevoegde inzage kan leiden tot privacy-inbreuken en AVG-risico’s.
A31: 30
A32: 31
A33: 32
A34: 33
A35: 34
A36: 35
A37: 36
A38: 37
A39: 38
A40: 39
...

Sheet 03_Kroonjuwelen
A1: Nr | B1: Asset | C1: Laag | D1: Waarom kroonjuweel? | E1: Impact bij uitval | F1: Geraakte processen
A2: 1 | B2: EZPD | C2: Informatie-, data- en applicatielaag | D2: Primair zorginformatiesysteem met medische kerngegevens. | E2: Direct risico voor patientveiligheid, zorg kan niet worden geleverd. | F2: Zorgverlening, medicatiebeheer, diagnostiek.
A3: 2 | B3: Zorgverlening | C3: Bedrijfsprocessenlaag | D3: Kernproces van de organisatie, medewerkers kunnen hun werk niet uitvoeren. | E3: Directe verstoring of stopzetting van zorg. | F3: Patient behandeling, overdracht, acute zorg.
A4: 3 | B4: Cloudomgeving (EZPD hosting) | C4: Infrastructuurlaag | D4: EZPD is afhankelijk van deze hybride cloudomgeving, waarbij het gehost wordt op interne en externe netwerk. | E4: Uitval van EZPD en digitale zorg. | F4: Zorgverlening, patiëntendossiers. Het vastleggen en raadplegen van patiëntgegevens, medicatiebeheer, diagnostiek en behandelplannen en communicatie met externe zorgpartners (zoals laboratoria).
A5: 4 | B5: Identity Management (Vanguard Healthcare) | C5: Informatie-, data- en applicatielaag | D5: Regelt toegang tot gebruikersaccounts. | E5: Geen toegang tot systemen of onbevoegde toegang. | F5: Alle zorg- en ondersteunende processen. Medewerkers kunnen niet in hun gebruikersaccount.
A6: 5 | B6: Netwerkinfrastructuur | C6: Infrastructuurlaag | D6: Verbindt locaties, systemen en gebruikers. | E6: Geen systeemtoegang en communicatie. | F6: Zorgverlening, externe samenwerking. Alle assets liggen plat.
A7: 6
A8: 7
A9: 8
A10: 9
A11: 10

Sheet 04_Wetgeving_Risicos
A1: Nr | B1: Wet / Richtlijn | C1: Asset | D1: Dreiging | E1: Kwetsbaarheid | F1: Impact | G1: Wet-artikel / Principe | H1: Toelichting
A2: 1 | B2: AVG | C2: EZPD | D2: Onbevoegde inzage / misbruik van patiëntgegevens. | E2: Rolautorisaties niet altijd actueel, MFA niet organisatiebreed afgedwongen. | F2: Een datalek kan mogelijk een zorgvertraging veroorzaken. | G2: Art. 5 lid 1 sub f AVG (Beginselen inzake verwerking van persoonsgegevens), Art. 32 lid 1 AVG (Beveiliging van de verwerking). | H2: Het EZPD bevat bijzondere persoonsgegevens (medische dossiers). Onjuiste autorisaties of ontbrekende MFA kan leiden tot onbevoegde inzage en een datalek. Dit kan meldplicht en reputatieschade veroorzaken.
A3: 2 | B3: AVG | C3: DLO | D3: Onbedoelde openbaarmaking van (herleidbare) patiëntinformatie. | E3: Casussen/reflectieverslagen niet altijd goed geanonimiseerd, autorisaties/oud-stagiair accounts niet opgeschoond. | F3: Het is mogelijk dat onbevoegden toegang krijgen tot patiëntinformatie. | G3: Art. 9 lid 1 AVG (Verwerking van bijzondere categorieën van persoonsgegevens), Art. 32 AVG (Beveiliging van de verwerking). | H3: In de DLO worden casussen gebruikt die soms indirect herleidbaar zijn. Als (ex-)stagiairs te brede toegang hebben, ontstaat een onrechtmatige verwerking en datalek-risico.
A4: 3 | B4: AVG | C4: Gebruikersaccounts / Identity Management | D4: Accountovername door phishing. | E4: Wachtwoordhergebruik, beperkte security awareness, MFA niet voor alle gebruikers verplicht. | F4: Dit vergroot de kans op datalekken en daardoor kan manipulatie van dossiers plaatsvinden. | G4: Art. 32 AVG (Beveiliging van de verwerking), Art. 33 AVG (Melding van een inbreuk in verband met persoonsgegevens aan de autoriteit toezichthoudende autoriteit), Art. 34 AVG (Mededeling van een inbreuk in verband met persoonsgegevens aan de betrokkene). | H4: Er is al een phishing-incident geweest. Met een overgenomen account kan een aanvaller medische gegevens inzien of wijzigen, wat leidt tot datalekken en mogelijke patiëntveiligheidsimpact.
A5: 4 | B5: AVG | C5: Vanguard Connect | D5: Datalek via internet-exposed portaal/API-koppelingen. | E5: Direct aan internet blootgesteld, API-koppelingen (REST/FHIR) kunnen foutief geconfigureerd of onvoldoende gelogd zijn. | F5: Onbevoegden kunnen mogelijk toegang krijgen tot patiëntgegevens of systemen, wat kan leiden tot privacy-schending en verstoring van de continuïteit van zorg op afstand. | G5: Art. 5 lid 1 sub f AVG (Beginselen inzake verwerking van persoonsgegevens), Art. 32 lid 1 AVG (Beveiliging van de verwerking), Art. 25 AVG (Gegevensbescherming door ontwerp en door standaardinstellingen). | H5: Vanguard Connect verwerkt medische gegevens en is een primair patiëntenportaal. Kwetsbaarheden in webapp/API’s kunnen leiden tot grootschalige blootstelling van patiëntdata.
A6: 5 | B6: NIS2 | C6: EZPD (cloud/hybride hosting) | D6: Onbeschikbaarheid door storing bij cloudleverancier. | E6: Sterke afhankelijkheid van externe leverancier, beperkte zichtbaarheid op back-up/BCP. | F6: Een storing of incident bij de cloudleverancier kan de continuïteit van de zorg verstoren en de patiëntveiligheid in gevaar brengen. | G6: Art. 21 lid 2 sub b en c Cyberbeveiligingswet (Cybersecurity riskmanagement measures), Art. 23 lid 1 en 4 Cyberbeveiligingswet (reporting obligations). | H6: Er was al downtime door een netwerkissue bij de leverancier. Onbeschikbaarheid van EZPD verstoort medicatie, diagnostiek en overdracht van patiëntinformatie.
A7: 6 | B7: NIS2 | C7: Netwerkinfrastructuur | D7: Ransomware/ malware verspreiding binnen organisatie. | E7: Mix van oude en nieuwe systemen, beperkte monitoring, processen vooral reactief. | F7: Zorgproces kan stilvallen door verstoringen. | G7: Art. 21 Cyberbeveiligingswet ( Cybersecurity riskmanagement measures), Art. 23 lid 1 en 4 Cyberbeveiligingswet (reporting obligations). | H7: Ransomware kan kernsystemen versleutelen en locaties ontregelen. Voor een zorginstelling heeft dit direct impact op continuïteit en patiëntveiligheid en vereist snelle incidentrespons.
A8: 7 | B8: NIS2 | C8: Medische IoT-apparatuur | D8: Compromitteren van medische apparatuur (malware/remote exploit). | E8: Verouderde software, geen structurele updates, soms op hetzelfde segment als werkplekken. | F8: Patiëntveiligheid kan in gevaar komen door kwetsbaarheden of systeemstoringen. | G8: Art. 21 lid 2 sub e, i en j Cyberbeveiligingwet (Cybersecurity riskmanagement measures). | H8: Medische apparatuur is functioneel noodzakelijk, maar vormt een aanvalsvlak. Compromittering kan monitoring of toediening beïnvloeden en daarmee direct risico geven voor patiënten.
A9: 8 | B9: NIS2 | C9: Netwerkinfrastructuur (OT/PLC gekoppeld) | D9: Cyberaanval op PLC/HMI (slimme verlichting SEH/ICU), verstoring kritieke zorgomgeving. | E9: OT-componenten gekoppeld aan netwerk, signalen van ongewenste lichtfluctuaties. | F9: Patiëntveiligheid kan worden bedreigd door storingen in kritische systemen. | G9: Art. 21 lid 2 sub a, b, c (Cybersecurity riskmanagement measures). | H9: Verlichting op SEH/ICU is onderdeel van kritieke processen. Manipulatie kan zorgmomenten verstoren en vraagt om OT-segmentatie, monitoring en incidentprocedures.
A10: 9 | B10: NIS2/ AVG (verwerkers) | C10: Samenwerking met externe partijen | D10: Beveiligingsincident of non-compliance bij leverancier, impact op Vanguard. | E10: Contracten/SLA’s historisch gegroeid en niet aantoonbaar afgestemd op actuele eisen, beperkte auditbaarheid. | F10: Ketenrisico en compliance-problemen kunnen leiden tot verstoring van zorg en aansprakelijkheid. | G10: Art. 21 lid 2 sub d (Cybersecurity riskmanagement measures), Art. 28 AVG (Verwerker). | H10: Vanguard gebruikt cloud/ICT/IoT leveranciers en blijft eindverantwoordelijk voor continuïteit en privacy. Onvoldoende ketenafspraken vergroten risico op uitval, datalekken en auditbevindingen.
A11: 10 | B11: NIS2/ AVG | C11: VPN voor Externe zorgprofessionals | D11: Onbevoegde toegang via externe accounts/VPN. | E11: VPN-toegang wordt niet standaard per kwartaal herzien, externe accounts (tijdelijke rollen) kunnen blijven bestaan. | F11: Onbevoegden kunnen toegang krijgen, wat kan leiden tot datalekken of ongeautoriseerde acties. | G11: Art. 21 lid 2 sub i en j Cyberbeveiligingswet (Cybersecurity riskmanagement measures), Art. 32 AVG (Beveiliging van de verwerking). | H11: Externe zorgprofessionals hebben toegang tot interne systemen. Zonder periodieke recertificatie en strakke offboarding kan ongeautoriseerde toegang ontstaan, met direct datalek- en patiëntveiligheidsrisico.
A12: 11 | F12: AVG | G12: NIS2
A13: 12 | E13: Bronnen | F13: https://gdpr-text.com/nl/ | G13: https://www.nis-2-directive.com/NIS_2_Directive_Articles.html
A14: 13
A15: 14
A16: 15
A17: 16
A18: 17
A19: 18 | K19: FALSE
A20: 19
A21: 20
A22: 21
A23: 22
A24: 23
A25: 24
A26: 25
A27: 26
A28: 27
A29: 28
A30: 29
A31: 30
... A201: 200

Sheet 05_Ketenanalyse
A1: Nr | B1: Leverancier | C1: Dienst | D1: Geraakte assets | E1: Afhankelijkheid | F1: Ketenrisico | G1: Impact
A2: 1 | B2: EZPD-cloudleverancier | C2: Hosting, beheer, updates en back-updiensten voor EZPD (hybride cloud). | D2: EZPD, patiëntdossiers, medicatiegegevens, labkoppelingen. | E2: Hoog (24/7 afhankelijk voor primaire zorgprocessen). | F2: Storing bij cloudleverancier of falend herstelproces, EZPD onbeschikbaar, zorgproces vertraagt/stopt, meldplicht-risico bij datalek. | G2: Continuïteit, patiëntveiligheid, compliance.
A3: 2 | B3: Microsoft/Azure AD (Identity/Federatie) | C3: Identity provider, federatieve authenticatie voor zorgverleners, mail/tenantdiensten. | D3: IAM, Vanguard Connect-toegang, interne accounts, e-mail. | E3: Hoog (centrale toegangspoort tot meerdere systemen). | F3: Uitval of compromise van identity-keten, geen toegang of ongeautoriseerde toegang tot kritieke zorgsystemen. | G3: Toegangscontinuïteit, security.
A4: 3 | B4: Extern diagnostisch laboratorium | C4: Aanlevering labuitslagen via API/portaal naar EZPD. | D4: EZPD, diagnostiek-workflow, patiëntgegevens. | E4: Middel (diagnostiek en behandeling afhankelijk van tijdige/integere data). | F4: Koppelingsstoring of datamanipulatie in de keten, vertraagde of foutieve uitslagen, risico op verkeerde behandelbeslissing. | G4: Integriteit, patiëntveiligheid.
A5: 4 | B5: Leverancier medische IoT-monitoring | C5: Medische apparatuur, devicebeheer en datadoorstuur naar EZPD. | D5: Medische IoT, monitoringdata, netwerksegmenten. | E5: Hoog (direct in zorgproces en patiëntmonitoring). | F5: Kwetsbare firmware of onveilige leveranciersupdate (supply-chain), compromittering apparatuur of datastroom. | G5: Beschikbaarheid, integriteit, patiëntveiligheid.
A6: 5 | B6: Externe ICT-partner (netwerkbeheer op afroep) | C6: Ondersteuning netwerkbeheer, storingsopvolging en wijzigingen. | D6: WAN/LAN, routers/switches, VPN, firewallconfiguraties. | E6: Middel (operationele ondersteuning, vooral bij incidenten). | F6: Onvoldoende contractuele responsetijden/security-eisen, trage incidentafhandeling en langere verstoring. | G6: Responstijd, herstel, auditbaarheid.
A7: 6 | B7: KPN WAN-provider | C7: Glasvezel WAN-verbinding tussen locaties. | D7: Interlocatieverkeer, toegang tot centrale systemen/EZPD. | E7: Hoog (meerdere locaties afhankelijk van dezelfde keten). | F7: Providerstoring of enkelvoudige afhankelijkheid, locaties geïsoleerd en toegang tot centrale zorgsystemen beperkt. | G7: Continuïteit en bedrijfsvoering.
A8: 7
A9: 8
A10: 9
A11: 10
A12: 11
A13: 12
A14: 13
A15: 14
A16: 15
A17: 16
A18: 17
A19: 18
... A101: 100

Sheet 06_Risicoregister
A1: Risico-ID | B1: Laag | C1: Asset | D1: Dreiging | E1: Kwetsbaarheid | F1: B | G1: I | H1: V | I1: Kans | J1: Impact | K1: Score (num) | L1: Risico (L/M/H) | M1: NIST | N1: ISO/NEN | P1: Instructie
A2: =IF(COUNTA(C2:E2)>0,"R"&ROW()-1,"") -> R1 | B2: Menselijkelaag | C2: EZPD, Vanguard Connect en gebruikersaccounts | D2: Phishing / credential theft leidt tot ongeautoriseerde toegang | E2: Awareness/werkdruk; hergebruik wachtwoorden; MFA niet organisatiebreed; beperkte monitoring | F2: M | G2: H | H2: H | I2: H | J2: H | K2: =IF(OR(I2="",J2=""),"",IFERROR(VLOOKUP(I2,'99_Lookups'!$A$2:$B$4,2,FALSE),"")*IFERROR(VLOOKUP(J2,'99_Lookups'!$A$2:$B$4,2,FALSE),"")) -> 9 | L2: =IF(K2="","",IF(K2<=3,"Laag",IF(K2<=6,"Midden","Hoog"))) -> Hoog | M2: Protect | N2: ISO 27005 (risicoanalyse); NEN 7510 (bewustwording & toegangsbeveiliging) | P2: Vul Kans en Impact in als L/M/H. Score en Risico worden automatisch berekend.
A3: =IF(COUNTA(C3:E3)>0,"R"&ROW()-1,"") -> R2 | B3: Infrastructuur laag | C3: Cloud hosting, Identity Management | D3: Account takeover / brute-force / password spraying | E3: MFA alleen voor beheerders; inconsistent afdwingen sterke authenticatie; onvoldoende detectie op verdachte logins | F3: H | G3: H | H3: H | I3: M | J3: H | K3: =IF(OR(I3="",J3=""),"",IFERROR(VLOOKUP(I3,'99_Lookups'!$A$2:$B$4,2,FALSE),"")*IFERROR(VLOOKUP(J3,'99_Lookups'!$A$2:$B$4,2,FALSE),"")) -> 6 | L3: =IF(K3="","",IF(K3<=3,"Laag",IF(K3<=6,"Midden","Hoog"))) -> Midden | M3: Protect | N3: ISO 27005; NEN 7510 (authenticatie/autorisa tie)
A4: =IF(COUNTA(C4:E4)>0,"R"&ROW()-1,"") -> R3 | B4: Bedrijfsprocessenlaag | C4: DLO | D4: Ongewenste inzage door (ex-)stagiairs/studenten | E4: Accounts niet tijdig gedeprovisioneerd; autorisaties niet actueel; toegangsgroepen niet periodiek gereviewd | F4: L | G4: M | H4: H | I4: M | J4: H | K4: =IF(OR(I4="",J4=""),"",IFERROR(VLOOKUP(I4,'99_Lookups'!$A$2:$B$4,2,FALSE),"")*IFERROR(VLOOKUP(J4,'99_Lookups'!$A$2:$B$4,2,FALSE),"")) -> 6 | L4: =IF(K4="","",IF(K4<=3,"Laag",IF(K4<=6,"Midden","Hoog"))) -> Midden | M4: Identify | N4: ISO 27005; NEN 7510 (toegangsbeheer, account lifecycle)
A5: =IF(COUNTA(C5:E5)>0,"R"&ROW()-1,"") -> R4 | B5: Bedrijfsprocessenlaag | C5: DLO + reflectieverslagen/casussen gebaseerd op echte zorgsituaties | D5: Privacy-incident door herleidbare patiëntinformatie in leeromgeving | E5: Anonimisering faalt in praktijk; onvoldoende richtlijnen/controle; brede deelrechten | F5: L | G5: M | H5: H | I5: M | J5: H | K5: =IF(OR(I5="",J5=""),"",IFERROR(VLOOKUP(I5,'99_Lookups'!$A$2:$B$4,2,FALSE),"")*IFERROR(VLOOKUP(J5,'99_Lookups'!$A$2:$B$4,2,FALSE),"")) -> 6 | L5: =IF(K5="","",IF(K5<=3,"Laag",IF(K5<=6,"Midden","Hoog"))) -> Midden | M5: Protect | N5: ISO 27005; NEN 7510 (privacybescherming, classificatie)
A6: =IF(COUNTA(C6:E6)>0,"R"&ROW()-1,"") -> R5 | B6: Bedrijfsprocessenlaag | C6: HR en Planning + Identity management | D6: Privilege creep / onjuiste autorisaties na functiewijzigingen | E6: Autorisaties afhankelijk van correcte invoer; functiewijzigingen/contract-einde niet tijdig verwerkt | F6: L | G6: H | H6: H | I6: M | J6: H | K6: =IF(OR(I6="",J6=""),"",IFERROR(VLOOKUP(I6,'99_Lookups'!$A$2:$B$4,2,FALSE),"")*IFERROR(VLOOKUP(J6,'99_Lookups'!$A$2:$B$4,2,FALSE),"")) -> 6 | L6: =IF(K6="","",IF(K6<=3,"Laag",IF(K6<=6,"Midden","Hoog"))) -> Midden | M6: Identify | N6: ISO 27005; NEN 7510 (autorisatiebeheer, SoD)
A7: =IF(COUNTA(C7:E7)>0,"R"&ROW()-1,"") -> R6 | B7: Infrastructuurlaag | C7: VPN-toegang voor externe zorgprofessionals | D7: Misbruik van VPN-account of compromised endpoint leidt tot netwerktoegang | E7: VPN-toegang niet standaard per kwartaal herzien; beperkte device-compliance checks | F7: M | G7: H | H7: H | I7: M | J7: H | K7: =IF(OR(I7="",J7=""),"",IFERROR(VLOOKUP(I7,'99_Lookups'!$A$2:$B$4,2,FALSE),"")*IFERROR(VLOOKUP(J7,'99_Lookups'!$A$2:$B$4,2,FALSE),"")) -> 6 | L7: =IF(K7="","",IF(K7<=3,"Laag",IF(K7<=6,"Midden","Hoog"))) -> Midden | M7: Protect | N7: ISO 27005; NEN 7510 (remote access, endpoint security)
A8: =IF(COUNTA(C8:E8)>0,"R"&ROW()-1,"") -> R7 | B8: Informatie, data- en applicatielaag | C8: Cloudomgeving | D8: Onbeschikbaarheid door storing bij cloudleverancier | E8: Afhankelijkheid externe leverancier; beperkte zichtbaarheid op SLA/BCP; eerdere downtime (2 uur) | F8: H | G8: M | H8: M | I8: M | J8: H | K8: =IF(OR(I8="",J8=""),"",IFERROR(VLOOKUP(I8,'99_Lookups'!$A$2:$B$4,2,FALSE),"")*IFERROR(VLOOKUP(J8,'99_Lookups'!$A$2:$B$4,2,FALSE),"")) -> 6 | L8: =IF(K8="","",IF(K8<=3,"Laag",IF(K8<=6,"Midden","Hoog"))) -> Midden | M8: Recover | N8: ISO 27005; NEN 7510 (continuïteit/BCM)
A9: =IF(COUNTA(C9:E9)>0,"R"&ROW()-1,"") -> R8 | B9: Informatie, data- en applicatielaag | C9: Systeem Back-ups | D9: Ransomware of datacorruptie → herstel faalt / lange uitval | E9: Back-ups deels leverancier-beheerd; beperkte interne zichtbaarheid/testen; onduidelijke RTO/RPO | F9: H | G9: H | H9: M | I9: M | J9: H | K9: =IF(OR(I9="",J9=""),"",IFERROR(VLOOKUP(I9,'99_Lookups'!$A$2:$B$4,2,FALSE),"")*IFERROR(VLOOKUP(J9,'99_Lookups'!$A$2:$B$4,2,FALSE),"")) -> 6 | L9: =IF(K9="","",IF(K9<=3,"Laag",IF(K9<=6,"Midden","Hoog"))) -> Midden | M9: Recover | N9: ISO 27005; NEN 7510 (back-up, hersteltesten)
A10: =IF(COUNTA(C10:E10)>0,"R"&ROW()-1,"") -> R9 | B10: Infrastructuurlaag | C10: Medische IoT-apparatuur | D10: Exploit van kwetsbare IoT leidt tot verstoring of datamanipulatie | E10: Verouderde software; geen structurele patching; beperkte hardening; leverancier-afhankelijk | F10: H | G10: H | H10: M | I10: M | J10: H | K10: =IF(OR(I10="",J10=""),"",IFERROR(VLOOKUP(I10,'99_Lookups'!$A$2:$B$4,2,FALSE),"")*IFERROR(VLOOKUP(J10,'99_Lookups'!$A$2:$B$4,2,FALSE),"")) -> 6 | L10: =IF(K10="","",IF(K10<=3,"Laag",IF(K10<=6,"Midden","Hoog"))) -> Midden | M10: Protect | N10: ISO 27005; NEN 7510 (patchmanagement, asset management)
A11: =IF(COUNTA(C11:E11)>0,"R"&ROW()-1,"") -> R10 | B11: Infrastructuurlaag | C11: Netwerksegmentatie (IoT vs werkplekken) | D11: Laterale beweging van werkplek naar medische apparatuur of EZPD | E11: IoT-apparatuur zit op sommige afdelingen in hetzelfde segment als werkplekken | F11: H | G11: H | H11: H | I11: M | J11: H | K11: =IF(OR(I11="",J11=""),"",IFERROR(VLOOKUP(I11,'99_Lookups'!$A$2:$B$4,2,FALSE),"")*IFERROR(VLOOKUP(J11,'99_Lookups'!$A$2:$B$4,2,FALSE),"")) -> 6 | L11: =IF(K11="","",IF(K11<=3,"Laag",IF(K11<=6,"Midden","Hoog"))) -> Midden | M11: Protect | N11: ISO 27005; NEN 7510 (netwerksegmentatie, least privilege)
A12: =IF(COUNTA(C12:E12)>0,"R"&ROW()-1,"") -> R11 | B12: Infrastructuurlaag | C12: Routers/Switches | D12: Een aanvaller die het netwerk binnendringt via de beheer ingang | E12: Telnet actief; SNMP community 'public' met read-write; (plain-text) wachtwoorden in config | F12: H | G12: H | H12: H | I12: H | J12: H | K12: =IF(OR(I12="",J12=""),"",IFERROR(VLOOKUP(I12,'99_Lookups'!$A$2:$B$4,2,FALSE),"")*IFERROR(VLOOKUP(J12,'99_Lookups'!$A$2:$B$4,2,FALSE),"")) -> 9 | L12: =IF(K12="","",IF(K12<=3,"Laag",IF(K12<=6,"Midden","Hoog"))) -> Hoog | M12: Protect | N12: ISO 27005; NEN 7510 (netwerkbeheer, veilige configuratie)
A13: =IF(COUNTA(C13:E13)>0,"R"&ROW()-1,"") -> R12 | B13: Infrastructuurlaag | C13: PLC-gestuurde slimme verlichting (SEH/ICU) | D13: Cyberaanval op PLC, ongewenste lichtfluctuaties tijdens kritieke zorg | E13: PLC verbonden met netwerk; OT-security/monitoring beperkt; al meldingen van fluctuaties | F13: H | G13: M | H13: M | I13: M | J13: H | K13: =IF(OR(I13="",J13=""),"",IFERROR(VLOOKUP(I13,'99_Lookups'!$A$2:$B$4,2,FALSE),"")*IFERROR(VLOOKUP(J13,'99_Lookups'!$A$2:$B$4,2,FALSE),"")) -> 6 | L13: =IF(K13="","",IF(K13<=3,"Laag",IF(K13<=6,"Midden","Hoog"))) -> Midden | M13: Detect | N13: ISO 27005; IEC 62443 (OT); NEN 7510 (continuïteit/patiëntveiligheid)
A14: =IF(COUNTA(C14:E14)>0,"R"&ROW()-1,"") | K14: =IF(OR(I14="",J14=""),"",IFERROR(VLOOKUP(I14,'99_Lookups'!$A$2:$B$4,2,FALSE),"")*IFERROR(VLOOKUP(J14,'99_Lookups'!$A$2:$B$4,2,FALSE),"")) | L14: =IF(K14="","",IF(K14<=3,"Laag",IF(K14<=6,"Midden","Hoog")))
A15: =IF(COUNTA(C15:E15)>0,"R"&ROW()-1,"") | K15: =IF(OR(I15="",J15=""),"",IFERROR(VLOOKUP(I15,'99_Lookups'!$A$2:$B$4,2,FALSE),"")*IFERROR(VLOOKUP(J15,'99_Lookups'!$A$2:$B$4,2,FALSE),"")) | L15: =IF(K15="","",IF(K15<=3,"Laag",IF(K15<=6,"Midden","Hoog")))
A16: =IF(COUNTA(C16:E16)>0,"R"&ROW()-1,"") | K16: =IF(OR(I16="",J16=""),"",IFERROR(VLOOKUP(I16,'99_Lookups'!$A$2:$B$4,2,FALSE),"")*IFERROR(VLOOKUP(J16,'99_Lookups'!$A$2:$B$4,2,FALSE),"")) | L16: =IF(K16="","",IF(K16<=3,"Laag",IF(K16<=6,"Midden","Hoog")))
A17: =IF(COUNTA(C17:E17)>0,"R"&ROW()-1,"") | K17: =IF(OR(I17="",J17=""),"",IFERROR(VLOOKUP(I17,'99_Lookups'!$A$2:$B$4,2,FALSE),"")*IFERROR(VLOOKUP(J17,'99_Lookups'!$A$2:$B$4,2,FALSE),"")) | L17: =IF(K17="","",IF(K17<=3,"Laag",IF(K17<=6,"Midden","Hoog")))
A18: =IF(COUNTA(C18:E18)>0,"R"&ROW()-1,"") | K18: =IF(OR(I18="",J18=""),"",IFERROR(VLOOKUP(I18,'99_Lookups'!$A$2:$B$4,2,FALSE),"")*IFERROR(VLOOKUP(J18,'99_Lookups'!$A$2:$B$4,2,FALSE),"")) | L18: =IF(K18="","",IF(K18<=3,"Laag",IF(K18<=6,"Midden","Hoog")))
A19: =IF(COUNTA(C19:E19)>0,"R"&ROW()-1,"") | K19: =IF(OR(I19="",J19=""),"",IFERROR(VLOOKUP(I19,'99_Lookups'!$A$2:$B$4,2,FALSE),"")*IFERROR(VLOOKUP(J19,'99_Lookups'!$A$2:$B$4,2,FALSE),"")) | L19: =IF(K19="","",IF(K19<=3,"Laag",IF(K19<=6,"Midden","Hoog")))
A20: =IF(COUNTA(C20:E20)>0,"R"&ROW()-1,"") | K20: =IF(OR(I20="",J20=""),"",IFERROR(VLOOKUP(I20,'99_Lookups'!$A$2:$B$4,2,FALSE),"")*IFERROR(VLOOKUP(J20,'99_Lookups'!$A$2:$B$4,2,FALSE),"")) | L20: =IF(K20="","",IF(K20<=3,"Laag",IF(K20<=6,"Midden","Hoog")))
A21: =IF(COUNTA(C21:E21)>0,"R"&ROW()-1,"") | K21: =IF(OR(I21="",J21=""),"",IFERROR(VLOOKUP(I21,'99_Lookups'!$A$2:$B$4,2,FALSE),"")*IFERROR(VLOOKUP(J21,'99_Lookups'!$A$2:$B$4,2,FALSE),"")) | L21: =IF(K21="","",IF(K21<=3,"Laag",IF(K21<=6,"Midden","Hoog")))
A22: =IF(COUNTA(C22:E22)>0,"R"&ROW()-1,"") | K22: =IF(OR(I22="",J22=""),"",IFERROR(VLOOKUP(I22,'99_Lookups'!$A$2:$B$4,2,FALSE),"")*IFERROR(VLOOKUP(J22,'99_Lookups'!$A$2:$B$4,2,FALSE),"")) | L22: =IF(K22="","",IF(K22<=3,"Laag",IF(K22<=6,"Midden","Hoog")))
A23: =IF(COUNTA(C23:E23)>0,"R"&ROW()-1,"") | K23: =IF(OR(I23="",J23=""),"",IFERROR(VLOOKUP(I23,'99_Lookups'!$A$2:$B$4,2,FALSE),"")*IFERROR(VLOOKUP(J23,'99_Lookups'!$A$2:$B$4,2,FALSE),"")) | L23: =IF(K23="","",IF(K23<=3,"Laag",IF(K23<=6,"Midden","Hoog")))
A24: =IF(COUNTA(C24:E24)>0,"R"&ROW()-1,"") | K24: =IF(OR(I24="",J24=""),"",IFERROR(VLOOKUP(I24,'99_Lookups'!$A$2:$B$4,2,FALSE),"")*IFERROR(VLOOKUP(J24,'99_Lookups'!$A$2:$B$4,2,FALSE),"")) | L24: =IF(K24="","",IF(K24<=3,"Laag",IF(K24<=6,"Midden","Hoog")))
A25: =IF(COUNTA(C25:E25)>0,"R"&ROW()-1,"") | K25: =IF(OR(I25="",J25=""),"",IFERROR(VLOOKUP(I25,'99_Lookups'!$A$2:$B$4,2,FALSE),"")*IFERROR(VLOOKUP(J25,'99_Lookups'!$A$2:$B$4,2,FALSE),"")) | L25: =IF(K25="","",IF(K25<=3,"Laag",IF(K25<=6,"Midden","Hoog")))
... A201: =IF(COUNTA(C201:E201)>0,"R"&ROW()-1,"") | K201: =IF(OR(I201="",J201=""),"",IFERROR(VLOOKUP(I201,'99_Lookups'!$A$2:$B$4,2,FALSE),"")*IFERROR(VLOOKUP(J201,'99_Lookups'!$A$2:$B$4,2,FALSE),"")) | L201: =IF(K201="","",IF(K201<=3,"Laag",IF(K201<=6,"Midden","Hoog")))

Sheet 07_Risicomatrix
A1: Risicomatrix (aantal risico's)
A3: Kans \ Impact | B3: Laag | C3: Midden | D3: Hoog | F3: Legenda
A4: Laag | B4: =COUNTIFS('06_Risicoregister'!$I$2:$I$200,"L",'06_Risicoregister'!$J$2:$J$200,"L") -> 0 | C4: =COUNTIFS('06_Risicoregister'!$I$2:$I$200,"L",'06_Risicoregister'!$J$2:$J$200,"M") -> 0 | D4: =COUNTIFS('06_Risicoregister'!$I$2:$I$200,"L",'06_Risicoregister'!$J$2:$J$200,"H") -> 0 | F4: Laag=L
A5: Midden | B5: =COUNTIFS('06_Risicoregister'!$I$2:$I$200,"M",'06_Risicoregister'!$J$2:$J$200,"L") -> 0 | C5: =COUNTIFS('06_Risicoregister'!$I$2:$I$200,"M",'06_Risicoregister'!$J$2:$J$200,"M") -> 0 | D5: =COUNTIFS('06_Risicoregister'!$I$2:$I$200,"M",'06_Risicoregister'!$J$2:$J$200,"H") -> 10 | F5: Midden=M | G5: Impact
A6: Hoog | B6: =COUNTIFS('06_Risicoregister'!$I$2:$I$200,"H",'06_Risicoregister'!$J$2:$J$200,"L") -> 0 | C6: =COUNTIFS('06_Risicoregister'!$I$2:$I$200,"H",'06_Risicoregister'!$J$2:$J$200,"M") -> 0 | D6: =COUNTIFS('06_Risicoregister'!$I$2:$I$200,"H",'06_Risicoregister'!$J$2:$J$200,"H") -> 2 | F6: Hoog=H
C8: Kans

Sheet 08_Scenarioanalyse
A1: Nr | B1: Risico-ID | C1: Trigger | D1: Kwetsbaarheid | E1: Aanvalspad (stappen 1–7) | F1: Impact (incl. patiëntveiligheid) | G1: Detectie faalt omdat | H1: Geraakte lagen
A2: 1
A3: 2
A4: 3
A5: 4
A6: 5
A7: 6
A8: 7
A9: 8
A10: 9
A11: 10
A12: 11
A13: 12
... A101: 100

Sheet 09_Top5_Risicos
A1: Rang | B1: Risico-ID | C1: Score | D1: Omschrijving (asset + dreiging) | E1: Waarom top 5 | F1: Patiëntimpact | G1: Compliance-impact
A2: 1 | B2: =IF(C3="","",INDEX('06_Risicoregister'!$A$2:$A$200,MATCH(C2,'06_Risicoregister'!$K$2:$K$200,0))) -> R1 | C2: =IFERROR(LARGE('06_Risicoregister'!$K$2:$K$200,1),"") -> 9 | D2: =IF(B2="","",INDEX('06_Risicoregister'!$C$2:$C$200,MATCH(B2,'06_Risicoregister'!$A$2:$A$200,0))&" – "&INDEX('06_Risicoregister'!$D$2:$D$200,MATCH(B2,'06_Risicoregister'!$A$2:$A$200,0))) -> EZPD, Vanguard Connect en gebruikersaccounts – Phishing / credential theft leidt tot ongeautoriseerde toegang
A3: 2 | B3: =IF(C3="","",INDEX('06_Risicoregister'!$A$2:$A$200,MATCH(C3,'06_Risicoregister'!$K$2:$K$200,0))) -> R1 | C3: =IFERROR(LARGE('06_Risicoregister'!$K$2:$K$200,2),"") -> 9 | D3: =IF(B3="","",INDEX('06_Risicoregister'!$C$2:$C$200,MATCH(B3,'06_Risicoregister'!$A$2:$A$200,0))&" – "&INDEX('06_Risicoregister'!$D$2:$D$200,MATCH(B3,'06_Risicoregister'!$A$2:$A$200,0))) -> EZPD, Vanguard Connect en gebruikersaccounts – Phishing / credential theft leidt tot ongeautoriseerde toegang
A4: 3 | B4: =IF(C3="","",INDEX('06_Risicoregister'!$A$2:$A$200,MATCH(C4,'06_Risicoregister'!$K$2:$K$200,0))) -> R2 | C4: =IFERROR(LARGE('06_Risicoregister'!$K$2:$K$200,3),"") -> 6 | D4: =IF(B4="","",INDEX('06_Risicoregister'!$C$2:$C$200,MATCH(B4,'06_Risicoregister'!$A$2:$A$200,0))&" – "&INDEX('06_Risicoregister'!$D$2:$D$200,MATCH(B4,'06_Risicoregister'!$A$2:$A$200,0))) -> Cloud hosting, Identity Management – Account takeover / brute-force / password spraying
A5: 4 | B5: =IF(C3="","",INDEX('06_Risicoregister'!$A$2:$A$200,MATCH(C5,'06_Risicoregister'!$K$2:$K$200,0))) -> R2 | C5: =IFERROR(LARGE('06_Risicoregister'!$K$2:$K$200,4),"") -> 6 | D5: =IF(B5="","",INDEX('06_Risicoregister'!$C$2:$C$200,MATCH(B5,'06_Risicoregister'!$A$2:$A$200,0))&" – "&INDEX('06_Risicoregister'!$D$2:$D$200,MATCH(B5,'06_Risicoregister'!$A$2:$A$200,0))) -> Cloud hosting, Identity Management – Account takeover / brute-force / password spraying
A6: 5 | B6: =IF(C3="","",INDEX('06_Risicoregister'!$A$2:$A$200,MATCH(C6,'06_Risicoregister'!$K$2:$K$200,0))) -> R2 | C6: =IFERROR(LARGE('06_Risicoregister'!$K$2:$K$200,5),"") -> 6 | D6: =IF(B6="","",INDEX('06_Risicoregister'!$C$2:$C$200,MATCH(B6,'06_Risicoregister'!$A$2:$A$200,0))&" – "&INDEX('06_Risicoregister'!$D$2:$D$200,MATCH(B6,'06_Risicoregister'!$A$2:$A$200,0))) -> Cloud hosting, Identity Management – Account takeover / brute-force / password spraying

Sheet 10_Maatregelenplan
A1: Risico-ID | B1: Type maatregel | C1: Maatregel | D1: Rol (owner) | E1: Norm/Best practice | F1: Evidence (bewijs)

Sheet 11_Roadmap
A1: Fase | B1: Maatregel | C1: Risico-ID | D1: Verantwoordelijke | E1: Resultaat / KPI

Sheet 12_Reflectie
A1: Vraag | B1: Antwoord
A3: Wat was jouw rol in het team?
A4: Wat vond je het lastigst en waarom?
A5: Welke risico’s verrasten je het meest?
A6: Wat zou je in de praktijk anders doen?
A7: Welke informatie miste je in de casus en hoe zou je dat ophalen?
A8: Welke maatregel heeft volgens jou de grootste impact en waarom?
